Workbook

Sheet Ogólny 
B1: Plant Balanced Scorecard | Z1: Edycja | AB1: 01
C4: Zakład : | P4: Rok | R4: 2024 | U4: =TODAY() -> 46270 | W4: Przygotowany przez
P5: Data rewizji
A6: N
A7: MD | B7: MT | C7: OBSZAR | E7: WSKAŹNIK | H7: Jednostka | I7: Częstotliwość | J7: Typ wskaźnika | K7: Odpowiedzialność | M7: BENCHMARK TYC/SKA | N7: DOPUSZCZALNE LIMITY [%] | O7: =R4 -> 2024 | P7: 44927 | Q7: =DATE(R4,2,1) -> 45323 | R7: =DATE(R4,3,1) -> 45352 | S7: =DATE(R4,4,1) -> 45383 | T7: =DATE(R4,5,1) -> 45413 | U7: =DATE(R4,6,1) -> 45444 | V7: =DATE(R4,7,1) -> 45474 | W7: =DATE(R4,8,1) -> 45505 | X7: =DATE(R4,9,1) -> 45536 | Y7: =DATE(R4,10,1) -> 45566 | Z7: =DATE(R4,11,1) -> 45597 | AA7: =DATE(R4,12,1) -> 45627 | AB7: YTD
F8: Metoda liczenia | G8: Definicja | O8: CEL REZULTAT
A9: GD (SALES) | B9: SPRZEDAŻ | C9: SALES DIRECTOR | E9: WIELKOŚĆ SPRZEDAŻY NETTO | F9: Wielkość sprzedaży netto = Przychody brutto − Rabaty − Zwroty − Skonta Bezpośrednio ze sprawozdań finansowych | G9: Wielkość sprzedaży netto odnosi się do całkowitych przychodów ze sprzedaży produktów lub usług po odjęciu wszelkich rabatów, zwrotów i skont. Jest to miara efektywności sprzedaży i pokazuje, ile firma zarobiła na sprzedaży po uwzględnieniu zniżek i korekt. | H9: min. | I9: Miesiąc | J9: Rozliczeniowy | K9: Sprzedaż | O9: CEL
H10: LC/1000 | O10: Rezultat
E11: WIELKOŚĆ SPRZEDAŻY NETTO (eksport) | F11: j.w., dla sprzedaży eksportowej | G11: Jak wyżej, dla eksportu | H11: min. | I11: Miesiąc | J11: Rozliczeniowy | O11: CEL
H12: LC/1000 | O12: Rezultat
E13: WIELKOŚĆ SPRZEDAŻY NETTO (kraj) | F13: j.w., dla sprzedaży krajowej | G13: Jak wyżej, dla sprzedaży krajowej | H13: min. | I13: Miesiąc | J13: Rozliczeniowy | O13: CEL
H14: LC/1000 | O14: Rezultat
E15: WIELKOŚĆ SPRZEDAŻY NETTO (narastająco) | F15: j.w., narastająco | G15: Jak wyżej | H15: min. | I15: Miesiąc narastająco | J15: Rozliczeniowy | K15: Sprzedaż | O15: CEL
H16: LC/1000 | O16: Rezultat
E17: WIELKOŚĆ SPRZEDAŻY NETTO (w odniesieniu do budżetu) | F17: WIELKOŚĆ SPRZEDAŻY NETTO (w odniesieniu do budżetu) = Sprzedaż rzeczywista / Sprzedaż netto budżetowana x100% | G17: Wskaźnik, który mierzy, jak dobrze rzeczywista sprzedaż netto realizuje założenia budżetowe. Jest to wskaźnik wykorzystywany do oceny skuteczności zarządzania sprzedażą w kontekście zaplanowanych celów finansowych. | H17: min. | I17: Miesiąc | J17: Rozliczeniowy | K17: Sprzedaż | O17: CEL
H18: % | O18: Rezultat
E19: WIELKOŚĆ SPRZEDAŻY NETTO (w odniesieniu do prognozy) | F19: WIELKOŚĆ SPRZEDAŻY NETTO (w odniesieniu do prognozy) = Sprzedaż rzeczywista / Sprzedaż netto prognozowana x100% | G19: Wskaźnik, który mierzy, jak dobrze rzeczywista sprzedaż netto realizuje założenia prognozy. Jest to wskaźnik wykorzystywany do oceny skuteczności zarządzania sprzedażą w kontekście zaplanowanych celów finansowych. | H19: min. | I19: Miesiąc | J19: Rozliczeniowy | K19: Sprzedaż | O19: CEL
H20: LC/1000 | O20: Rezultat
E21: LICZBA NOWYCH WOLUMENÓW (BEZ MODYFIKACJI OBECNYCH) | F21: Kryterium "nowego wolumenu" - produkt który został wprowadzony na rynek po raz pierwszy w danym okresie i nie jest modyfikacją istniejącego produktu (np. nowe warianty kolorystyczne, wersje rozwojowe produktu, itp. nie są uwzględniane) | G21: Liczba sprzedanych nowych wolumenów odnosi się do liczby nowych produktów po raz pierwszy w danym okresie, które nie są modyfikacjami ani ulepszeniami istniejących produktów. Ten wskaźnik koncentruje się na innowacyjnych lub zupełnie nowych propozycjach wartości w ofercie firmy, będących wynikiem rozwoju nowych produktów lub usług. | H21: min. | I21: Miesiąc | J21: Informacyjny | K21: Sprzedaż | O21: CEL
H22: [szt.] | O22: Rezultat
E23: LICZBA NOWYCH KLIENTÓW | F23: Liczba nowych klientów = Liczba unikalnych klient ów w okresie − Liczba klientów już istniejących Kryterium "nowego klienta" - Klient, który dokonał pierwszego zakupu w danym okresie i nie figurował wcześniej w bazie klientów. | G23: Wskaźnik określający liczbę unikalnych klientów, którzy po raz pierwszy dokonali zakupu lub skorzystali z usług firmy w określonym okresie czasu. Jest to kluczowy wskaźnik w perspektywie klienta w ramach Balanced Scorecard (BSC), który odzwierciedla zdolność firmy do pozyskiwania nowych odbiorców swoich produktów lub usług. | H23: max. | I23: Miesiąc | J23: Informacyjny | K23: Sprzedaż | O23: CEL
H24: [szt.] | O24: Rezultat
C25: RSM/KAM | E25: WIELKOŚĆ SPRZEDAŻY (indywidualna) | F25: Wielkość sprzedaży indywidualna = Całkowita wartość sprzedaży przypisana do indywidualnego klienta/produktu/usługi | G25: Sprzedaż indywidualna odnosi się do wielkości sprzedaży powiązanej z określonym klientem, produktem lub usługą. | H25: min. | I25: Miesiąc | J25: Rozliczeniowy | K25: Sprzedaż | O25: CEL
H26: m2 | O26: Rezultat
E27: ŚREDNIA MARŻA | F27: Średnia marża = (Przychody ze sprzedaży - Koszty sprzedaży) / Przychody ze sprzedaży × 100 | G27: Średnia marża to różnica między przychodami ze sprzedaży a kosztami sprzedaży, wyrażona procentowo. | H27: max. | I27: Miesiąc | J27: Rozliczeniowy | K27: Sprzedaż | O27: CEL
H28: % | O28: Rezultat
E29: LICZBA NOWYCH WOLUMENÓW (BEZ MODYFIKACJI OBECNYCH) | F29: Liczba nowych wolumenów = Liczba nowych produktów lub usług wprowadzonych do sprzedaży w danym okresie | G29: Liczba nowych wolumenów to liczba nowych produktów lub usług wprowadzonych na rynek, bez modyfikacji istniejących. | H29: min. | I29: Miesiąc | J29: Informacyjny | O29: CEL
H30: [m2] | O30: Rezultat
E31: POZIOM OTWARTYCH ZAMÓWIEŃ | F31: Poziom otwartych zamówień = Łączna liczba zamówień niezrealizowanych w danym okresie | G31: Poziom otwartych zamówień mierzy liczbę zamówień klientów, które nie zostały jeszcze zrealizowane. | H31: min. | I31: Miesiąc | J31: Rozliczeniowy | K31: Sprzedaż | O31: CEL
H32: m2 | O32: Rezultat
E33: PROCENT REFAKTUROWANIA NARZĘDZI | F33: Procent refakturowania narzędzi = (Wartość narzędzi zrefakturowanych / Wartość wszystkich narzędzi) × 100 | G33: Procent refakturowania narzędzi mierzy udział narzędzi zrefakturowanych w stosunku do wszystkich używanych narzędzi. | H33: min. | I33: Miesiąc narastajaco | J33: Rozliczeniowy | K33: Sprzedaż | O33: CEL
H34: % | O34: Rezultat
E35: LICZBA NOWYCH KLIENTÓW | F35: Liczba nowych klientów = Klienci pozyskani w danym okresie | G35: wskaźnik mierzący ilość nowych klientów pozyskanych przez firmę w określonym czasie. Odzwierciedla zdolność firmy do przyciągania nowych odbiorców i poszerzania bazy klientów. | H35: min | I35: Miesiąc | J35: Rozliczeniowy | K35: Sprzedaż | O35: CEL
H36: szt. | O36: Rezultat
C37: CS | E37: POZIOM SATYSFAKCJI KLIENTÓW | F37: Nie ma uniwersalnego wzoru, jednak poziom satysfakcji klientów często mierzy się za pomocą ankiet (np. Net Promoter Score - NPS), które pytają klientów o ich poziom zadowolenia na skali punktowej. NPS = %promotorów − %krytyków | G37: wskaźnik mierzący stopień zadowolenia klientów z produktów, usług lub ogólnej współpracy z firmą. Jest to kluczowy wskaźnik jakości obsługi klienta i lojalności klientów wobec firmy. | H37: min. | I37: Kwartał | J37: Rozliczeniowy | O37: CEL
H38: % | O38: Rezultat
E39: STAN MAGAZYNU PALET (ŚREDNIA LICZBA PALET NIE WIĘCEJ NIŻ 5% POWYŻEJ LIMITU) | F39: Stan magazynu palet = Średnia liczba palet w magazynie / Ustalony limit palet ×100% | G39: wskaźnik logistyczny monitorujący, jak skutecznie firma utrzymuje zapasy palet w magazynie, zapewniając, że ich liczba nie przekracza ustalonego limitu o więcej niż 5%. | H39: min. | I39: Miesiąc | J39: Rozliczeniowy | O39: CEL
H40: szt. | O40: Rezultat
E41: NALEŻNOŚCI PRZETERMINOWANA POWYŻEJ 7 DNI | F41: Należności przeterminowane powyżej 7 dni = Wartość przeterminowanych należności powyżej 7 dni / Całkowita wartość należności ×100% | G41: wskaźnik finansowy mierzący wartość zobowiązań klientów wobec firmy, które nie zostały uregulowane w ciągu 7 dni od ustalonego terminu płatności. | H41: max. | I41: Miesiąc | J41: Rozliczeniowy | O41: CEL
H42: LC/1000 | O42: Rezultat
...

Sheet Arkusz1
A4: jak rozliczać nowy wolumne?

Sheet Karta wskaźnika PRZYKŁAD
A1: Sprzedaż netto | G1: Lata: | H1: ='Ogólny '!R4 -> 2024
A23: UWAGA - jeśli istnieje osobny plan działania lub opracowany dokument analizy przyczyny pierwotnej, w komórce "Komentarze" wystarczy przywołać dany dokument (nie ma potrzeby powielania informacji i działań).
A25: Miesiąc | B25: Czy osiągnięto cel? | C25: Czy wymagane są działania? | D25: Opis problemu | E25: Główna przyczyna | F25: Opis działań | G25: Odpowiedzialność | H25: Data zakończenia | J25: Komentarze | K25: Status (OTWARTY/ ZAMKNIĘTY)
A26: 44927
A27: 44958
A28: 44986
A29: 45017
A30: 45047
A31: 45078
A32: 45108
A33: 45139
A34: 45170
A35: 45200
A36: 45231
A37: 45261

Sheet Sprzedaż netto narastająco
A1: Sprzedaż netto narastająco | G1: Lata: | H1: ='Ogólny '!R4 -> 2024
I2: 1
A23: UWAGA - jeśli istnieje osobny plan działania lub opracowany dokument analizy przyczyny pierwotnej, w komórce "Komentarze" wystarczy przywołać dany dokument (nie ma potrzeby powielania informacji i działań).
A25: Miesiąc | B25: Czy osiągnięto cel? | C25: Czy wymagane są działania? | D25: Opis problemu | E25: Główna przyczyna | F25: Opis działań | G25: Odpowiedzialność | H25: Data zakończenia | J25: Komentarze | K25: Status (OTWARTY/ ZAMKNIĘTY)
A26: 43466
A27: 43497
A28: 43525
A29: 43556
A30: 43586
A31: 43617
A32: 43647
A33: 43678
A34: 43709
A35: 43739
A36: 43770
A37: 43800

Sheet Poziom przyjętych zamówień
A1: Poziom przyjętych zamówień | G1: Lata: | H1: ='Ogólny '!R4 -> 2024
A23: UWAGA - jeśli istnieje osobny plan działania lub opracowany dokument analizy przyczyny pierwotnej, w komórce "Komentarze" wystarczy przywołać dany dokument (nie ma potrzeby powielania informacji i działań).
A25: Miesiąc | B25: Czy osiągnięto cel? | C25: Czy wymagane są działania? | D25: Opis problemu | E25: Główna przyczyna | F25: Opis działań | G25: Odpowiedzialność | H25: Data zakończenia | J25: Komentarze | K25: Status (OTWARTY/ ZAMKNIĘTY)
A26: 43466
A27: 43497
A28: 43525
A29: 43556
A30: 43586
A31: 43617
A32: 43647
A33: 43678
A34: 43709
A35: 43739
A36: 43770
A37: 43800

Sheet Zużycie materiałów
A1: Zużycie materiałów | G1: Lata: | H1: ='Ogólny '!R4 -> 2024
A23: UWAGA - jeśli istnieje osobny plan działania lub opracowany dokument analizy przyczyny pierwotnej, w komórce "Komentarze" wystarczy przywołać dany dokument (nie ma potrzeby powielania informacji i działań).
A25: Miesiąc | B25: Czy osiągnięto cel? | C25: Czy wymagane są działania? | D25: Opis problemu | E25: Główna przyczyna | F25: Opis działań | G25: Odpowiedzialność | H25: Data zakończenia | J25: Komentarze | K25: Status (OTWARTY/ ZAMKNIĘTY)
A26: 43466
A27: 43497
A28: 43525
A29: 43556
A30: 43586
A31: 43617
A32: 43647
A33: 43678
A34: 43709
A35: 43739
A36: 43770
A37: 43800

Sheet Odpad technologiczny jakościowy
A1: Odpad technologiczny/jakościowy | G1: Lata: | H1: ='Ogólny '!R4 -> 2024
A23: UWAGA - jeśli istnieje osobny plan działania lub opracowany dokument analizy przyczyny pierwotnej, w komórce "Komentarze" wystarczy przywołać dany dokument (nie ma potrzeby powielania informacji i działań).
A25: Miesiąc | B25: Czy osiągnięto cel? | C25: Czy wymagane są działania? | D25: Opis problemu | E25: Główna przyczyna | F25: Opis działań | G25: Odpowiedzialność | H25: Data zakończenia | J25: Komentarze | K25: Status (OTWARTY/ ZAMKNIĘTY)
A26: 43466
A27: 43497
A28: 43525
A29: 43556
A30: 43586
A31: 43617
A32: 43647
A33: 43678
A34: 43709
A35: 43739
A36: 43770
A37: 43800

Sheet Kary
A1: Kary | G1: Lata: | H1: ='Ogólny '!R4 -> 2024
A23: UWAGA - jeśli istnieje osobny plan działania lub opracowany dokument analizy przyczyny pierwotnej, w komórce "Komentarze" wystarczy przywołać dany dokument (nie ma potrzeby powielania informacji i działań).
A25: Miesiąc | B25: Czy osiągnięto cel? | C25: Czy wymagane są działania? | D25: Opis problemu | E25: Główna przyczyna | F25: Opis działań | G25: Odpowiedzialność | H25: Data zakończenia | J25: Komentarze | K25: Status (OTWARTY/ ZAMKNIĘTY)
A26: 43466
A27: 43497
A28: 43525
A29: 43556
A30: 43586
A31: 43617
A32: 43647
A33: 43678
A34: 43709
A35: 43739
A36: 43770
A37: 43800

Sheet Koszt pracy bezpośredniej
A1: Koszt pracy bezpośredniej (udział) | G1: Lata: | H1: ='Ogólny '!R4 -> 2024
A23: UWAGA - jeśli istnieje osobny plan działania lub opracowany dokument analizy przyczyny pierwotnej, w komórce "Komentarze" wystarczy przywołać dany dokument (nie ma potrzeby powielania informacji i działań).
A25: Miesiąc | B25: Czy osiągnięto cel? | C25: Czy wymagane są działania? | D25: Opis problemu | E25: Główna przyczyna | F25: Opis działań | G25: Odpowiedzialność | H25: Data zakończenia | J25: Komentarze | K25: Status (OTWARTY/ ZAMKNIĘTY)
A26: 43466
A27: 43497
A28: 43525
A29: 43556
A30: 43586
A31: 43617
A32: 43647
A33: 43678
A34: 43709
A35: 43739
A36: 43770
A37: 43800

Sheet Koszt pracy niebezpośr.-prod.
A1: Koszt pracy niebezpośrednio-produkcyjnej | G1: Lata: | H1: ='Ogólny '!R4 -> 2024
A23: UWAGA - jeśli istnieje osobny plan działania lub opracowany dokument analizy przyczyny pierwotnej, w komórce "Komentarze" wystarczy przywołać dany dokument (nie ma potrzeby powielania informacji i działań).
A25: Miesiąc | B25: Czy osiągnięto cel? | C25: Czy wymagane są działania? | D25: Opis problemu | E25: Główna przyczyna | F25: Opis działań | G25: Odpowiedzialność | H25: Data zakończenia | J25: Komentarze | K25: Status (OTWARTY/ ZAMKNIĘTY)
A26: 43466
A27: 43497
A28: 43525
A29: 43556
A30: 43586
A31: 43617
A32: 43647
A33: 43678
A34: 43709
A35: 43739
A36: 43770
A37: 43800

Sheet Koszt transportu out
A1: Koszt transportu out | G1: Lata: | H1: ='Ogólny '!R4 -> 2024
A23: UWAGA - jeśli istnieje osobny plan działania lub opracowany dokument analizy przyczyny pierwotnej, w komórce "Komentarze" wystarczy przywołać dany dokument (nie ma potrzeby powielania informacji i działań).
A25: Miesiąc | B25: Czy osiągnięto cel? | C25: Czy wymagane są działania? | D25: Opis problemu | E25: Główna przyczyna | F25: Opis działań | G25: Odpowiedzialność | H25: Data zakończenia | J25: Komentarze | K25: Status (OTWARTY/ ZAMKNIĘTY)
A26: 43466
A27: 43497
A28: 43525
A29: 43556
A30: 43586
A31: 43617
A32: 43647
A33: 43678
A34: 43709
A35: 43739
A36: 43770
A37: 43800

Sheet Koszt transportu in
A1: Koszt transportu in | G1: Lata: | H1: ='Ogólny '!R4 -> 2024
A23: UWAGA - jeśli istnieje osobny plan działania lub opracowany dokument analizy przyczyny pierwotnej, w komórce "Komentarze" wystarczy przywołać dany dokument (nie ma potrzeby powielania informacji i działań).
A25: Miesiąc | B25: Czy osiągnięto cel? | C25: Czy wymagane są działania? | D25: Opis problemu | E25: Główna przyczyna | F25: Opis działań | G25: Odpowiedzialność | H25: Data zakończenia | J25: Komentarze | K25: Status (OTWARTY/ ZAMKNIĘTY)
A26: 43466
A27: 43497
A28: 43525
A29: 43556
A30: 43586
A31: 43617
A32: 43647
A33: 43678
A34: 43709
A35: 43739
A36: 43770
A37: 43800

Sheet Wynagrodzenie kadry
A1: Wynagrodzenie kadry | G1: Lata: | H1: ='Ogólny '!R4 -> 2024
A23: UWAGA - jeśli istnieje osobny plan działania lub opracowany dokument analizy przyczyny pierwotnej, w komórce "Komentarze" wystarczy przywołać dany dokument (nie ma potrzeby powielania informacji i działań).
A25: Miesiąc | B25: Czy osiągnięto cel? | C25: Czy wymagane są działania? | D25: Opis problemu | E25: Główna przyczyna | F25: Opis działań | G25: Odpowiedzialność | H25: Data zakończenia | J25: Komentarze | K25: Status (OTWARTY/ ZAMKNIĘTY)
A26: 43466
A27: 43497
A28: 43525
A29: 43556
A30: 43586
A31: 43617
A32: 43647
A33: 43678
A34: 43709
A35: 43739
A36: 43770
A37: 43800

Sheet Marża bezpośrednia
A1: Marża bezpośrednia | G1: Lata: | H1: ='Ogólny '!R4 -> 2024
A23: UWAGA - jeśli istnieje osobny plan działania lub opracowany dokument analizy przyczyny pierwotnej, w komórce "Komentarze" wystarczy przywołać dany dokument (nie ma potrzeby powielania informacji i działań).
A25: Miesiąc | B25: Czy osiągnięto cel? | C25: Czy wymagane są działania? | D25: Opis problemu | E25: Główna przyczyna | F25: Opis działań | G25: Odpowiedzialność | H25: Data zakończenia | J25: Komentarze | K25: Status (OTWARTY/ ZAMKNIĘTY)
A26: 43466
A27: 43497
A28: 43525
A29: 43556
A30: 43586
A31: 43617
A32: 43647
A33: 43678
A34: 43709
A35: 43739
A36: 43770
A37: 43800

Sheet Koszty wydziałowe
A1: Koszty wydziałowe | G1: Lata: | H1: ='Ogólny '!R4 -> 2024
A23: UWAGA - jeśli istnieje osobny plan działania lub opracowany dokument analizy przyczyny pierwotnej, w komórce "Komentarze" wystarczy przywołać dany dokument (nie ma potrzeby powielania informacji i działań).
A25: Miesiąc | B25: Czy osiągnięto cel? | C25: Czy wymagane są działania? | D25: Opis problemu | E25: Główna przyczyna | F25: Opis działań | G25: Odpowiedzialność | H25: Data zakończenia | J25: Komentarze | K25: Status (OTWARTY/ ZAMKNIĘTY)
A26: 43466
A27: 43497
A28: 43525
A29: 43556
A30: 43586
A31: 43617
A32: 43647
A33: 43678
A34: 43709
A35: 43739
A36: 43770
A37: 43800

Sheet EBITDA
A1: EBITDA | G1: Lata: | H1: ='Ogólny '!R4 -> 2024
A23: UWAGA - jeśli istnieje osobny plan działania lub opracowany dokument analizy przyczyny pierwotnej, w komórce "Komentarze" wystarczy przywołać dany dokument (nie ma potrzeby powielania informacji i działań).
A25: Miesiąc | B25: Czy osiągnięto cel? | C25: Czy wymagane są działania? | D25: Opis problemu | E25: Główna przyczyna | F25: Opis działań | G25: Odpowiedzialność | H25: Data zakończenia | J25: Komentarze | K25: Status (OTWARTY/ ZAMKNIĘTY)
A26: 43466
A27: 43497
A28: 43525
A29: 43556
A30: 43586
A31: 43617
A32: 43647
A33: 43678
A34: 43709
A35: 43739
A36: 43770
A37: 43800

Sheet CAPEX
A1: CAPEX | G1: Lata: | H1: ='Ogólny '!R4 -> 2024
A23: UWAGA - jeśli istnieje osobny plan działania lub opracowany dokument analizy przyczyny pierwotnej, w komórce "Komentarze" wystarczy przywołać dany dokument (nie ma potrzeby powielania informacji i działań).
A25: Miesiąc | B25: Czy osiągnięto cel? | C25: Czy wymagane są działania? | D25: Opis problemu | E25: Główna przyczyna | F25: Opis działań | G25: Odpowiedzialność | H25: Data zakończenia | J25: Komentarze | K25: Status (OTWARTY/ ZAMKNIĘTY)
A26: 43466
A27: 43497
A28: 43525
A29: 43556
A30: 43586
A31: 43617
A32: 43647
A33: 43678
A34: 43709
A35: 43739
A36: 43770
A37: 43800

Sheet Zwroty od klienta
A1: Zwroty od klienta | G1: Lata: | H1: ='Ogólny '!R4 -> 2024
A23: UWAGA - jeśli istnieje osobny plan działania lub opracowany dokument analizy przyczyny pierwotnej, w komórce "Komentarze" wystarczy przywołać dany dokument (nie ma potrzeby powielania informacji i działań).
A25: Miesiąc | B25: Czy osiągnięto cel? | C25: Czy wymagane są działania? | D25: Opis problemu | E25: Główna przyczyna | F25: Opis działań | G25: Odpowiedzialność | H25: Data zakończenia | J25: Komentarze | K25: Status (OTWARTY/ ZAMKNIĘTY)
A26: 43466
A27: 43497
A28: 43525
A29: 43556
A30: 43586
A31: 43617
A32: 43647
A33: 43678
A34: 43709
A35: 43739
A36: 43770
A37: 43800

Sheet Wymiana u klienta
A1: Wymiana u klienta | G1: Lata: | H1: ='Ogólny '!R4 -> 2024
A23: UWAGA - jeśli istnieje osobny plan działania lub opracowany dokument analizy przyczyny pierwotnej, w komórce "Komentarze" wystarczy przywołać dany dokument (nie ma potrzeby powielania informacji i działań).
A25: Miesiąc | B25: Czy osiągnięto cel? | C25: Czy wymagane są działania? | D25: Opis problemu | E25: Główna przyczyna | F25: Opis działań | G25: Odpowiedzialność | H25: Data zakończenia | J25: Komentarze | K25: Status (OTWARTY/ ZAMKNIĘTY)
A26: 43466
A27: 43497
A28: 43525
A29: 43556
A30: 43586
A31: 43617
A32: 43647
A33: 43678
A34: 43709
A35: 43739
A36: 43770
A37: 43800

Sheet Zwroty klientów (wewnętrzne)
A1: Zwroty klientów (wewnętrzne) | G1: Lata: | H1: ='Ogólny '!R4 -> 2024
A23: UWAGA - jeśli istnieje osobny plan działania lub opracowany dokument analizy przyczyny pierwotnej, w komórce "Komentarze" wystarczy przywołać dany dokument (nie ma potrzeby powielania informacji i działań).
A25: Miesiąc | B25: Czy osiągnięto cel? | C25: Czy wymagane są działania? | D25: Opis problemu | E25: Główna przyczyna | F25: Opis działań | G25: Odpowiedzialność | H25: Data zakończenia | J25: Komentarze | K25: Status (OTWARTY/ ZAMKNIĘTY)
A26: 43466
A27: 43497
A28: 43525
A29: 43556
A30: 43586
A31: 43617
A32: 43647
A33: 43678
A34: 43709
A35: 43739
A36: 43770
A37: 43800

Sheet Poziom Backlog
A1: Poziom Backlog | G1: Lata: | H1: ='Ogólny '!R4 -> 2024
A23: UWAGA - jeśli istnieje osobny plan działania lub opracowany dokument analizy przyczyny pierwotnej, w komórce "Komentarze" wystarczy przywołać dany dokument (nie ma potrzeby powielania informacji i działań).
A25: Miesiąc | B25: Czy osiągnięto cel? | C25: Czy wymagane są działania? | D25: Opis problemu | E25: Główna przyczyna | F25: Opis działań | G25: Odpowiedzialność | H25: Data zakończenia | J25: Komentarze | K25: Status (OTWARTY/ ZAMKNIĘTY)
A26: 43466
A27: 43497
A28: 43525
A29: 43556
A30: 43586
A31: 43617
A32: 43647
A33: 43678
A34: 43709
A35: 43739
A36: 43770
A37: 43800

Sheet Dostawy na czas
A1: Dostawy na czas | G1: Lata: | H1: ='Ogólny '!R4 -> 2024
A23: UWAGA - jeśli istnieje osobny plan działania lub opracowany dokument analizy przyczyny pierwotnej, w komórce "Komentarze" wystarczy przywołać dany dokument (nie ma potrzeby powielania informacji i działań).
A25: Miesiąc | B25: Czy osiągnięto cel? | C25: Czy wymagane są działania? | D25: Opis problemu | E25: Główna przyczyna | F25: Opis działań | G25: Odpowiedzialność | H25: Data zakończenia | J25: Komentarze | K25: Status (OTWARTY/ ZAMKNIĘTY)
A26: 43466
A27: 43497
A28: 43525
A29: 43556
A30: 43586
A31: 43617
A32: 43647
A33: 43678
A34: 43709
A35: 43739
A36: 43770
A37: 43800

Sheet OEE
A1: OEE na kluczowych stanowiskach (legalizacja mieszkaniowe) | G1: Lata: | H1: ='Ogólny '!R4 -> 2024
A23: UWAGA - jeśli istnieje osobny plan działania lub opracowany dokument analizy przyczyny pierwotnej, w komórce "Komentarze" wystarczy przywołać dany dokument (nie ma potrzeby powielania informacji i działań).
A25: Miesiąc | B25: Czy osiągnięto cel? | C25: Czy wymagane są działania? | D25: Opis problemu | E25: Główna przyczyna | F25: Opis działań | G25: Odpowiedzialność | H25: Data zakończenia | J25: Komentarze | K25: Status (OTWARTY/ ZAMKNIĘTY)
A26: 43466
A27: 43497
A28: 43525
A29: 43556
A30: 43586
A31: 43617
A32: 43647
A33: 43678
A34: 43709
A35: 43739
A36: 43770
A37: 43800

Sheet WIP
A1: WIP | G1: Lata: | H1: ='Ogólny '!R4 -> 2024
A23: UWAGA - jeśli istnieje osobny plan działania lub opracowany dokument analizy przyczyny pierwotnej, w komórce "Komentarze" wystarczy przywołać dany dokument (nie ma potrzeby powielania informacji i działań).
A25: Miesiąc | B25: Czy osiągnięto cel? | C25: Czy wymagane są działania? | D25: Opis problemu | E25: Główna przyczyna | F25: Opis działań | G25: Odpowiedzialność | H25: Data zakończenia | J25: Komentarze | K25: Status (OTWARTY/ ZAMKNIĘTY)
A26: 43466
A27: 43497
A28: 43525
A29: 43556
A30: 43586
A31: 43617
A32: 43647
A33: 43678
A34: 43709
A35: 43739
A36: 43770
A37: 43800

Sheet Materiał
A1: Materiał | G1: Lata: | H1: ='Ogólny '!R4 -> 2024
A23: UWAGA - jeśli istnieje osobny plan działania lub opracowany dokument analizy przyczyny pierwotnej, w komórce "Komentarze" wystarczy przywołać dany dokument (nie ma potrzeby powielania informacji i działań).
A25: Miesiąc | B25: Czy osiągnięto cel? | C25: Czy wymagane są działania? | D25: Opis problemu | E25: Główna przyczyna | F25: Opis działań | G25: Odpowiedzialność | H25: Data zakończenia | J25: Komentarze | K25: Status (OTWARTY/ ZAMKNIĘTY)
A26: 43466
A27: 43497
A28: 43525
A29: 43556
A30: 43586
A31: 43617
A32: 43647
A33: 43678
A34: 43709
A35: 43739
A36: 43770
A37: 43800

Sheet Wyroby gotowe
A1: Wyroby gotowe | G1: Lata: | H1: ='Ogólny '!R4 -> 2024
A23: UWAGA - jeśli istnieje osobny plan działania lub opracowany dokument analizy przyczyny pierwotnej, w komórce "Komentarze" wystarczy przywołać dany dokument (nie ma potrzeby powielania informacji i działań).
A25: Miesiąc | B25: Czy osiągnięto cel? | C25: Czy wymagane są działania? | D25: Opis problemu | E25: Główna przyczyna | F25: Opis działań | G25: Odpowiedzialność | H25: Data zakończenia | J25: Komentarze | K25: Status (OTWARTY/ ZAMKNIĘTY)
A26: 43466
A27: 43497
A28: 43525
A29: 43556
A30: 43586
A31: 43617
A32: 43647
A33: 43678
A34: 43709
A35: 43739
A36: 43770
A37: 43800

Sheet Towary
A1: Towary | G1: Lata: | H1: ='Ogólny '!R4 -> 2024
A23: UWAGA - jeśli istnieje osobny plan działania lub opracowany dokument analizy przyczyny pierwotnej, w komórce "Komentarze" wystarczy przywołać dany dokument (nie ma potrzeby powielania informacji i działań).
A25: Miesiąc | B25: Czy osiągnięto cel? | C25: Czy wymagane są działania? | D25: Opis problemu | E25: Główna przyczyna | F25: Opis działań | G25: Odpowiedzialność | H25: Data zakończenia | J25: Komentarze | K25: Status (OTWARTY/ ZAMKNIĘTY)
A26: 43466
A27: 43497
A28: 43525
A29: 43556
A30: 43586
A31: 43617
A32: 43647
A33: 43678
A34: 43709
A35: 43739
A36: 43770
A37: 43800

Sheet Współczynnik rotacji
A1: Współczynnik rotacji | G1: Lata: | H1: ='Ogólny '!R4 -> 2024
A23: UWAGA - jeśli istnieje osobny plan działania lub opracowany dokument analizy przyczyny pierwotnej, w komórce "Komentarze" wystarczy przywołać dany dokument (nie ma potrzeby powielania informacji i działań).
A25: Miesiąc | B25: Czy osiągnięto cel? | C25: Czy wymagane są działania? | D25: Opis problemu | E25: Główna przyczyna | F25: Opis działań | G25: Odpowiedzialność | H25: Data zakończenia | J25: Komentarze | K25: Status (OTWARTY/ ZAMKNIĘTY)
A26: 43466
A27: 43497
A28: 43525
A29: 43556
A30: 43586
A31: 43617
A32: 43647
A33: 43678
A34: 43709
A35: 43739
A36: 43770
A37: 43800

Sheet Absencja
A1: Absencja | G1: Lata: | H1: ='Ogólny '!R4 -> 2024
A23: UWAGA - jeśli istnieje osobny plan działania lub opracowany dokument analizy przyczyny pierwotnej, w komórce "Komentarze" wystarczy przywołać dany dokument (nie ma potrzeby powielania informacji i działań).
A25: Miesiąc | B25: Czy osiągnięto cel? | C25: Czy wymagane są działania? | D25: Opis problemu | E25: Główna przyczyna | F25: Opis działań | G25: Odpowiedzialność | H25: Data zakończenia | J25: Komentarze | K25: Status (OTWARTY/ ZAMKNIĘTY)
A26: 43466
A27: 43497
A28: 43525
A29: 43556
A30: 43586
A31: 43617
A32: 43647
A33: 43678
A34: 43709
A35: 43739
A36: 43770
A37: 43800

Sheet Poziom zaległych ulopów
A1: Poziom zaległych urlopów | G1: Lata: | H1: ='Ogólny '!R4 -> 2024
A23: UWAGA - jeśli istnieje osobny plan działania lub opracowany dokument analizy przyczyny pierwotnej, w komórce "Komentarze" wystarczy przywołać dany dokument (nie ma potrzeby powielania informacji i działań).
A25: Miesiąc | B25: Czy osiągnięto cel? | C25: Czy wymagane są działania? | D25: Opis problemu | E25: Główna przyczyna | F25: Opis działań | G25: Odpowiedzialność | H25: Data zakończenia | J25: Komentarze | K25: Status (OTWARTY/ ZAMKNIĘTY)
A26: 43466
A27: 43497
A28: 43525
A29: 43556
A30: 43586
A31: 43617
A32: 43647
A33: 43678
A34: 43709
A35: 43739
A36: 43770
A37: 43800

Sheet Ilość wypadków
A1: Ilość wypadków | G1: Lata: | H1: ='Ogólny '!R4 -> 2024
A23: UWAGA - jeśli istnieje osobny plan działania lub opracowany dokument analizy przyczyny pierwotnej, w komórce "Komentarze" wystarczy przywołać dany dokument (nie ma potrzeby powielania informacji i działań).
A25: Miesiąc | B25: Czy osiągnięto cel? | C25: Czy wymagane są działania? | D25: Opis problemu | E25: Główna przyczyna | F25: Opis działań | G25: Odpowiedzialność | H25: Data zakończenia | J25: Komentarze | K25: Status (OTWARTY/ ZAMKNIĘTY)
A26: 43466
A27: 43497
A28: 43525
A29: 43556
A30: 43586
A31: 43617
A32: 43647
A33: 43678
A34: 43709
A35: 43739
A36: 43770
A37: 43800

Sheet Zużycie energii elektrycznej
A1: Zużycie energii elektrycznej | G1: Lata: | H1: ='Ogólny '!R4 -> 2024
A23: UWAGA - jeśli istnieje osobny plan działania lub opracowany dokument analizy przyczyny pierwotnej, w komórce "Komentarze" wystarczy przywołać dany dokument (nie ma potrzeby powielania informacji i działań).
A25: Miesiąc | B25: Czy osiągnięto cel? | C25: Czy wymagane są działania? | D25: Opis problemu | E25: Główna przyczyna | F25: Opis działań | G25: Odpowiedzialność | H25: Data zakończenia | J25: Komentarze | K25: Status (OTWARTY/ ZAMKNIĘTY)
A26: 43466
A27: 43497
A28: 43525
A29: 43556
A30: 43586
A31: 43617
A32: 43647
A33: 43678
A34: 43709
A35: 43739
A36: 43770
A37: 43800

Sheet Zużycie wody
A1: Zużycie wody | G1: Lata: | H1: ='Ogólny '!R4 -> 2024
A23: UWAGA - jeśli istnieje osobny plan działania lub opracowany dokument analizy przyczyny pierwotnej, w komórce "Komentarze" wystarczy przywołać dany dokument (nie ma potrzeby powielania informacji i działań).
A25: Miesiąc | B25: Czy osiągnięto cel? | C25: Czy wymagane są działania? | D25: Opis problemu | E25: Główna przyczyna | F25: Opis działań | G25: Odpowiedzialność | H25: Data zakończenia | J25: Komentarze | K25: Status (OTWARTY/ ZAMKNIĘTY)
A26: 43466
A27: 43497
A28: 43525
A29: 43556
A30: 43586
A31: 43617
A32: 43647
A33: 43678
A34: 43709
A35: 43739
A36: 43770
A37: 43800

Sheet UR
C3: Do wprowadzenia
